{"uuid": "4f0a3196-ce54-4e31-924b-2bb892a2d75b", "children": ["3366e967-d49a-45e1-904d-b7106995f3c9", "9faf7678-704a-45fa-a2fd-3eb438e638a4", "f1d39a8b-8262-44e9-93fb-bb62d8e2046a", "d2ea55a3-ad56-4562-9586-2ef6edad089f"], "befores": [{"name": "driver", "status": "broken", "statusDetails": {"message": "selenium.common.exceptions.WebDriverException: Message: An unknown server-side error occurred while processing the command. Original error: The application at '/Users/kevin/automated-testing/Apps2pay/MINT/MINT_Loket/src/app/LOKET MINT_1.24.06.02_Production.apk' does not exist or is not accessible\nStacktrace:\nUnknownError: An unknown server-side error occurred while processing the command. Original error: The application at '/Users/kevin/automated-testing/Apps2pay/MINT/MINT_Loket/src/app/LOKET MINT_1.24.06.02_Production.apk' does not exist or is not accessible\n    at getResponseForW3CError (/usr/local/lib/node_modules/appium/node_modules/@appium/base-driver/lib/protocol/errors.js:1145:9)\n    at asyncHandler (/usr/local/lib/node_modules/appium/node_modules/@appium/base-driver/lib/protocol/protocol.js:485:57)\n", "trace": "  File \"/Users/kevin/automated-testing/Apps2pay/MINT/MINT_Loket/venv/lib/python3.10/site-packages/pluggy/_callers.py\", line 103, in _multicall\n    res = hook_impl.function(*args)\n  File \"/Users/kevin/automated-testing/Apps2pay/MINT/MINT_Loket/venv/lib/python3.10/site-packages/_pytest/fixtures.py\", line 1111, in pytest_fixture_setup\n    result = call_fixture_func(fixturefunc, request, kwargs)\n  File \"/Users/kevin/automated-testing/Apps2pay/MINT/MINT_Loket/venv/lib/python3.10/site-packages/_pytest/fixtures.py\", line 883, in call_fixture_func\n    fixture_result = next(generator)\n  File \"/Users/kevin/automated-testing/Apps2pay/MINT/MINT_Loket/src/conftest.py\", line 22, in driver\n    driver = webdriver.Remote('http://localhost:4723', options=options)\n  File \"/Users/kevin/automated-testing/Apps2pay/MINT/MINT_Loket/venv/lib/python3.10/site-packages/appium/webdriver/webdriver.py\", line 229, in __init__\n    super().__init__(\n  File \"/Users/kevin/automated-testing/Apps2pay/MINT/MINT_Loket/venv/lib/python3.10/site-packages/selenium/webdriver/remote/webdriver.py\", line 212, in __init__\n    self.start_session(capabilities)\n  File \"/Users/kevin/automated-testing/Apps2pay/MINT/MINT_Loket/venv/lib/python3.10/site-packages/appium/webdriver/webdriver.py\", line 319, in start_session\n    response = self.execute(RemoteCommand.NEW_SESSION, w3c_caps)\n  File \"/Users/kevin/automated-testing/Apps2pay/MINT/MINT_Loket/venv/lib/python3.10/site-packages/selenium/webdriver/remote/webdriver.py\", line 354, in execute\n    self.error_handler.check_response(response)\n  File \"/Users/kevin/automated-testing/Apps2pay/MINT/MINT_Loket/venv/lib/python3.10/site-packages/selenium/webdriver/remote/errorhandler.py\", line 229, in check_response\n    raise exception_class(message, screen, stacktrace)\n"}, "start": 1727082958943, "stop": 1727082959675}], "start": 1727082958943, "stop": 1727082960129}