{"uuid": "5778380f-5d50-4136-95b9-d840be46b1c8", "children": ["d98e0cea-bf7e-4b62-a1ff-ffa83aaa57f1", "8c874dc9-8985-4b5b-9756-f4d5ffb7663b", "d4b5407a-ac2b-4349-9cd5-6361b2b28800"], "befores": [{"name": "driver", "status": "passed", "start": 1727253760439, "stop": 1727253775904}], "afters": [{"name": "driver::0", "status": "broken", "statusDetails": {"message": "selenium.common.exceptions.WebDriverException: Message: An unknown server-side error occurred while processing the command. Original error: Error executing adbExec. Original error: 'Command '/Users/kevin/Library/Android/sdk/platform-tools/adb -P 5037 -s 1902390100180748 shell 'settings delete global hidden_api_policy_pre_p_apps;settings delete global hidden_api_policy_p_apps;settings delete global hidden_api_policy'' exited with code 1'; Command output: adb: device offline\n\nStacktrace:\nUnknownError: An unknown server-side error occurred while processing the command. Original error: Error executing adbExec. Original error: 'Command '/Users/kevin/Library/Android/sdk/platform-tools/adb -P 5037 -s 1902390100180748 shell 'settings delete global hidden_api_policy_pre_p_apps;settings delete global hidden_api_policy_p_apps;settings delete global hidden_api_policy'' exited with code 1'; Command output: adb: device offline\n\n    at getResponseForW3CError (/usr/local/lib/node_modules/appium/node_modules/@appium/base-driver/lib/protocol/errors.js:1145:9)\n    at asyncHandler (/usr/local/lib/node_modules/appium/node_modules/@appium/base-driver/lib/protocol/protocol.js:485:57)\n", "trace": "  File \"/Users/kevin/automated-testing/Apps2pay/MINT/MINT_Loket/venv/lib/python3.10/site-packages/allure_commons/_allure.py\", line 200, in __call__\n    return self._fixture_function(*args, **kwargs)\n  File \"/Users/kevin/automated-testing/Apps2pay/MINT/MINT_Loket/venv/lib/python3.10/site-packages/_pytest/fixtures.py\", line 899, in _teardown_yield_fixture\n    next(it)\n  File \"/Users/kevin/automated-testing/Apps2pay/MINT/MINT_Loket/src/conftest.py\", line 26, in driver\n    driver.quit()\n  File \"/Users/kevin/automated-testing/Apps2pay/MINT/MINT_Loket/venv/lib/python3.10/site-packages/selenium/webdriver/remote/webdriver.py\", line 476, in quit\n    self.execute(Command.QUIT)\n  File \"/Users/kevin/automated-testing/Apps2pay/MINT/MINT_Loket/venv/lib/python3.10/site-packages/selenium/webdriver/remote/webdriver.py\", line 354, in execute\n    self.error_handler.check_response(response)\n  File \"/Users/kevin/automated-testing/Apps2pay/MINT/MINT_Loket/venv/lib/python3.10/site-packages/appium/webdriver/errorhandler.py\", line 125, in check_response\n    raise exception_class(msg=message, stacktrace=format_stacktrace(stacktrace))\n"}, "start": 1727253830991, "stop": 1727253835964}], "start": 1727253760439, "stop": 1727253835965}