{"uuid": "d060251a-c474-4042-856c-3536c9276759", "children": ["8c387ff3-134d-4c2c-baec-8dcf85706b29", "114ee680-15be-4464-92a1-f76238a01f44", "8716fcff-1395-45e5-8eda-d71db4ad7bb2", "9ac4f0b2-5528-43dc-97da-1ac1a2036ca9", "73c2d637-be77-4c16-9d30-0eb1b7923809"], "befores": [{"name": "driver", "status": "broken", "statusDetails": {"message": "selenium.common.exceptions.WebDriverException: Message: An unknown server-side error occurred while processing the command. Original error: Error getting device API level. Original error: Error executing adbExec. Original error: 'Command '/Users/kevin/Library/Android/sdk/platform-tools/adb -P 5037 -s 1902390100180748 shell getprop ro.build.version.sdk' exited with code 1'; Command output: adb: device '1902390100180748' not found\n\nStacktrace:\nUnknownError: An unknown server-side error occurred while processing the command. Original error: Error getting device API level. Original error: Error executing adbExec. Original error: 'Command '/Users/kevin/Library/Android/sdk/platform-tools/adb -P 5037 -s 1902390100180748 shell getprop ro.build.version.sdk' exited with code 1'; Command output: adb: device '1902390100180748' not found\n\n    at getResponseForW3CError (/usr/local/lib/node_modules/appium/node_modules/@appium/base-driver/lib/protocol/errors.js:1145:9)\n    at asyncHandler (/usr/local/lib/node_modules/appium/node_modules/@appium/base-driver/lib/protocol/protocol.js:485:57)\n", "trace": "  File \"/Users/kevin/automated-testing/Apps2pay/MINT/MINT_Loket/venv/lib/python3.10/site-packages/pluggy/_callers.py\", line 103, in _multicall\n    res = hook_impl.function(*args)\n  File \"/Users/kevin/automated-testing/Apps2pay/MINT/MINT_Loket/venv/lib/python3.10/site-packages/_pytest/fixtures.py\", line 1111, in pytest_fixture_setup\n    result = call_fixture_func(fixturefunc, request, kwargs)\n  File \"/Users/kevin/automated-testing/Apps2pay/MINT/MINT_Loket/venv/lib/python3.10/site-packages/_pytest/fixtures.py\", line 883, in call_fixture_func\n    fixture_result = next(generator)\n  File \"/Users/kevin/automated-testing/Apps2pay/MINT/MINT_Loket/src/conftest.py\", line 22, in driver\n    driver = webdriver.Remote('http://localhost:4723', options=options)\n  File \"/Users/kevin/automated-testing/Apps2pay/MINT/MINT_Loket/venv/lib/python3.10/site-packages/appium/webdriver/webdriver.py\", line 229, in __init__\n    super().__init__(\n  File \"/Users/kevin/automated-testing/Apps2pay/MINT/MINT_Loket/venv/lib/python3.10/site-packages/selenium/webdriver/remote/webdriver.py\", line 212, in __init__\n    self.start_session(capabilities)\n  File \"/Users/kevin/automated-testing/Apps2pay/MINT/MINT_Loket/venv/lib/python3.10/site-packages/appium/webdriver/webdriver.py\", line 319, in start_session\n    response = self.execute(RemoteCommand.NEW_SESSION, w3c_caps)\n  File \"/Users/kevin/automated-testing/Apps2pay/MINT/MINT_Loket/venv/lib/python3.10/site-packages/selenium/webdriver/remote/webdriver.py\", line 354, in execute\n    self.error_handler.check_response(response)\n  File \"/Users/kevin/automated-testing/Apps2pay/MINT/MINT_Loket/venv/lib/python3.10/site-packages/selenium/webdriver/remote/errorhandler.py\", line 229, in check_response\n    raise exception_class(message, screen, stacktrace)\n"}, "start": 1727166236744, "stop": 1727166238789}], "start": 1727166236744, "stop": 1727166239613}