{"uuid": "25f24941-169f-41bd-aba1-6bf34ffc8b82", "children": ["c45d5c23-407c-4d76-a74a-6295692e8716", "6f8dbbf0-b8e2-443d-8dc4-c9cf231204ac"], "befores": [{"name": "driver", "status": "broken", "statusDetails": {"message": "selenium.common.exceptions.WebDriverException: Message: An unknown server-side error occurred while processing the command. Original error: The application at '/Users/kevin/automated-testing/Apps2pay/MINT/MINT_Loket/src/app/LOKET MINT_1.24.06.02_Production.apk' does not exist or is not accessible\nStacktrace:\nUnknownError: An unknown server-side error occurred while processing the command. Original error: The application at '/Users/kevin/automated-testing/Apps2pay/MINT/MINT_Loket/src/app/LOKET MINT_1.24.06.02_Production.apk' does not exist or is not accessible\n    at getResponseForW3CError (/usr/local/lib/node_modules/appium/node_modules/@appium/base-driver/lib/protocol/errors.js:1145:9)\n    at asyncHandler (/usr/local/lib/node_modules/appium/node_modules/@appium/base-driver/lib/protocol/protocol.js:485:57)\n", "trace": "  File \"/Users/kevin/automated-testing/Apps2pay/MINT/MINT_Loket/venv/lib/python3.10/site-packages/pluggy/_callers.py\", line 103, in _multicall\n    res = hook_impl.function(*args)\n  File \"/Users/kevin/automated-testing/Apps2pay/MINT/MINT_Loket/venv/lib/python3.10/site-packages/_pytest/fixtures.py\", line 1111, in pytest_fixture_setup\n    result = call_fixture_func(fixturefunc, request, kwargs)\n  File \"/Users/kevin/automated-testing/Apps2pay/MINT/MINT_Loket/venv/lib/python3.10/site-packages/_pytest/fixtures.py\", line 883, in call_fixture_func\n    fixture_result = next(generator)\n  File \"/Users/kevin/automated-testing/Apps2pay/MINT/MINT_Loket/src/conftest.py\", line 22, in driver\n    driver = webdriver.Remote('http://localhost:4723', options=options)\n  File \"/Users/kevin/automated-testing/Apps2pay/MINT/MINT_Loket/venv/lib/python3.10/site-packages/appium/webdriver/webdriver.py\", line 229, in __init__\n    super().__init__(\n  File \"/Users/kevin/automated-testing/Apps2pay/MINT/MINT_Loket/venv/lib/python3.10/site-packages/selenium/webdriver/remote/webdriver.py\", line 212, in __init__\n    self.start_session(capabilities)\n  File \"/Users/kevin/automated-testing/Apps2pay/MINT/MINT_Loket/venv/lib/python3.10/site-packages/appium/webdriver/webdriver.py\", line 319, in start_session\n    response = self.execute(RemoteCommand.NEW_SESSION, w3c_caps)\n  File \"/Users/kevin/automated-testing/Apps2pay/MINT/MINT_Loket/venv/lib/python3.10/site-packages/selenium/webdriver/remote/webdriver.py\", line 354, in execute\n    self.error_handler.check_response(response)\n  File \"/Users/kevin/automated-testing/Apps2pay/MINT/MINT_Loket/venv/lib/python3.10/site-packages/selenium/webdriver/remote/errorhandler.py\", line 229, in check_response\n    raise exception_class(message, screen, stacktrace)\n"}, "start": 1727082750125, "stop": 1727082750947}], "start": 1727082750125, "stop": 1727082751280}